Workbook

Sheet About_This_Data
A1: Field | B1: Value
A2: Company | B2: Northstar Water Services - fictional water-pipe maintenance and service company
A3: Reporting date | B3: 46295
A4: Scope | B4: 120 Q3 2026 work orders, five sites. All identities and records are synthetic.
A5: Meaning | B5: Cost is cumulative recorded cost of all statuses; not a budget or productivity claim.
A6: Rejoin | B6: This input is a deterministic checkpoint, not proof of your Copilot output.

Sheet Work_Orders
A1: Work_Order_ID | B1: Site | C1: Job_Category | D1: Priority | E1: Status | F1: Assigned_To | G1: Opened_Date | H1: Due_Date | I1: Closed_Date | J1: Estimated_Hours | K1: Actual_Hours | L1: Cost_SGD | M1: Description
A2: WO-2026-0001 | B2: Woodlands Hub | C2: Leak Repair | D2: Low | E2: Closed | F2: Aisha Tan | G2: 46290 | H2: 46297 | I2: 46295 | J2: 2 | K2: 1 | L2: 90 | M2: Leak Repair scheduled or reactive task 001
A3: WO-2026-0002 | B3: Woodlands Hub | C3: Leak Repair | D3: Medium | E3: Closed | F3: Ben Lim | G3: 46289 | H3: 46297 | I3: 46295 | J3: 3 | K3: 2 | L3: 125.5 | M3: Leak Repair scheduled or reactive task 002
A4: WO-2026-0003 | B4: Woodlands Hub | C4: Leak Repair | D4: High | E4: In Progress | F4: Chloe Goh | G4: 46288 | H4: 46297 | J4: 4 | K4: 0 | L4: 161 | M4: Leak Repair scheduled or reactive task 003
A5: WO-2026-0004 | B5: Jurong Depot | C5: Leak Repair | D5: Critical | E5: On Hold | F5: Daniel Lee | G5: 46287 | H5: 46297 | J5: 5 | K5: 0 | L5: 196.5 | M5: Leak Repair scheduled or reactive task 004
A6: WO-2026-0005 | B6: Jurong Depot | C6: Valve Repair | D6: Low | E6: New | F6: Elena Ong | G6: 46286 | H6: 46297 | J6: 6 | K6: 0 | L6: 232 | M6: Valve Repair scheduled or reactive task 005
A7: WO-2026-0006 | B7: Jurong Depot | C7: Valve Repair | D7: Medium | E7: Closed | F7: Farid Rahman | G7: 46285 | H7: 46297 | I7: 46295 | J7: 7 | K7: 6 | L7: 267.5 | M7: Valve Repair scheduled or reactive task 006
A8: WO-2026-0007 | B8: Tampines Centre | C8: Valve Repair | D8: High | E8: Closed | F8: Grace Ng | G8: 46284 | H8: 46297 | I8: 46295 | J8: 8 | K8: 7 | L8: 303 | M8: Valve Repair scheduled or reactive task 007
A9: WO-2026-0008 | B9: Tampines Centre | C9: Valve Repair | D9: Critical | E9: On Hold | F9: Hari Kumar | G9: 46283 | H9: 46297 | J9: 2 | K9: 0 | L9: 338.5 | M9: Valve Repair scheduled or reactive task 008
A10: WO-2026-0009 | B10: Tampines Centre | C10: Pipe Replacement | D10: Low | E10: New | F10: Aisha Tan | G10: 46282 | H10: 46297 | J10: 3 | K10: 0 | L10: 374 | M10: Pipe Replacement scheduled or reactive task 009
A11: WO-2026-0010 | B11: Paya Lebar Office | C11: Pipe Replacement | D11: Medium | E11: Cancelled | F11: Ben Lim | G11: 46281 | H11: 46297 | J11: 4 | K11: 0 | L11: 409.5 | M11: Pipe Replacement scheduled or reactive task 010
A12: WO-2026-0011 | B12: Paya Lebar Office | C12: Pipe Replacement | D12: High | E12: Closed | F12: Chloe Goh | G12: 46280 | H12: 46287 | I12: 46287 | J12: 5 | K12: 2 | L12: 445 | M12: Pipe Replacement scheduled or reactive task 011
A13: WO-2026-0012 | B13: Paya Lebar Office | C13: Pipe Replacement | D13: Critical | E13: Closed | F13: Daniel Lee | G13: 46279 | H13: 46287 | I13: 46287 | J13: 6 | K13: 3 | L13: 480.5 | M13: Pipe Replacement scheduled or reactive task 012
A14: WO-2026-0013 | B14: Changi Workshop | C14: Pump Service | D14: Low | E14: New | G14: 46278 | H14: 46287 | J14: 7 | K14: 0 | L14: 516 | M14: Pump Service scheduled or reactive task 013
A15: WO-2026-0014 | B15: Changi Workshop | C15: Pump Service | D15: Medium | E15: Assigned | F15: Farid Rahman | G15: 46277 | H15: 46287 | J15: 8 | K15: 0 | L15: 90 | M15: Pump Service scheduled or reactive task 014
A16: WO-2026-0015 | B16: Changi Workshop | C16: Pump Service | D16: High | E16: In Progress | F16: Grace Ng | G16: 46276 | H16: 46287 | J16: 2 | K16: 0 | L16: 125.5 | M16: Pump Service scheduled or reactive task 015
A17: WO-2026-0016 | B17: Woodlands Hub | C17: Pump Service | D17: Critical | E17: Closed | F17: Hari Kumar | G17: 46275 | H17: 46287 | I17: 46288 | J17: 3 | K17: 7 | L17: 161 | M17: Pump Service scheduled or reactive task 016
A18: WO-2026-0017 | B18: Woodlands Hub | C18: Meter Service | D18: Low | E18: Closed | F18: Aisha Tan | G18: 46274 | H18: 46287 | I18: 46288 | J18: 4 | K18: 8 | L18: 196.5 | M18: Meter Service scheduled or reactive task 017
A19: WO-2026-0018 | B19: Woodlands Hub | C19: Meter Service | D19: Medium | E19: Assigned | F19: Ben Lim | G19: 46273 | H19: 46287 | J19: 5 | K19: 0 | L19: 232 | M19: Meter Service scheduled or reactive task 018
A20: WO-2026-0019 | B20: Jurong Depot | C20: Meter Service | D20: High | E20: In Progress | F20: Chloe Goh | G20: 46272 | H20: 46287 | J20: 6 | K20: 0 | L20: 267.5 | M20: Meter Service scheduled or reactive task 019
A21: WO-2026-0020 | B21: Jurong Depot | C21: Meter Service | D21: Critical | E21: Cancelled | F21: Daniel Lee | G21: 46271 | H21: 46287 | J21: 7 | K21: 0 | L21: 303 | M21: Meter Service scheduled or reactive task 020
A22: WO-2026-0021 | B22: Jurong Depot | C22: Leak Repair | D22: Low | E22: Closed | F22: Elena Ong | G22: 46270 | H22: 46277 | I22: 46279 | J22: 8 | K22: 3 | L22: 338.5 | M22: Leak Repair scheduled or reactive task 021
A23: WO-2026-0022 | B23: Tampines Centre | C23: Leak Repair | D23: Medium | E23: Closed | F23: Farid Rahman | G23: 46269 | H23: 46277 | I23: 46279 | J23: 2 | K23: 4 | L23: 374 | M23: Leak Repair scheduled or reactive task 022
A24: WO-2026-0023 | B24: Tampines Centre | C24: Leak Repair | D24: High | E24: In Progress | F24: Grace Ng | G24: 46268 | H24: 46277 | J24: 3 | K24: 0 | L24: 409.5 | M24: Leak Repair scheduled or reactive task 023
A25: WO-2026-0024 | B25: Tampines Centre | C25: Leak Repair | D25: Critical | E25: On Hold | F25: Hari Kumar | G25: 46267 | H25: 46277 | J25: 4 | K25: 0 | L25: 445 | M25: Leak Repair scheduled or reactive task 024
A26: WO-2026-0025 | B26: Paya Lebar Office | C26: Valve Repair | D26: Low | E26: New | G26: 46266 | H26: 46277 | J26: 5 | K26: 0 | L26: 480.5 | M26: Valve Repair scheduled or reactive task 025
A27: WO-2026-0026 | B27: Paya Lebar Office | C27: Valve Repair | D27: Medium | E27: Closed | F27: Ben Lim | G27: 46265 | H27: 46277 | I27: 46275 | J27: 6 | K27: 8 | L27: 516 | M27: Valve Repair scheduled or reactive task 026
A28: WO-2026-0027 | B28: Paya Lebar Office | C28: Valve Repair | D28: High | E28: Closed | F28: Chloe Goh | G28: 46264 | H28: 46277 | I28: 46275 | J28: 7 | K28: 9 | L28: 90 | M28: Valve Repair scheduled or reactive task 027
A29: WO-2026-0028 | B29: Changi Workshop | C29: Valve Repair | D29: Critical | E29: On Hold | F29: Daniel Lee | G29: 46263 | H29: 46277 | J29: 8 | K29: 0 | L29: 125.5 | M29: Valve Repair scheduled or reactive task 028
A30: WO-2026-0029 | B30: Changi Workshop | C30: Pipe Replacement | D30: Low | E30: New | F30: Elena Ong | G30: 46262 | H30: 46277 | J30: 2 | K30: 0 | L30: 161 | M30: Pipe Replacement scheduled or reactive task 029
A31: WO-2026-0030 | B31: Changi Workshop | C31: Pipe Replacement | D31: Medium | E31: Cancelled | F31: Farid Rahman | G31: 46261 | H31: 46277 | J31: 3 | K31: 0 | L31: 196.5 | M31: Pipe Replacement scheduled or reactive task 030
A32: WO-2026-0031 | B32: Woodlands Hub | C32: Pipe Replacement | D32: High | E32: Closed | F32: Grace Ng | G32: 46260 | H32: 46267 | I32: 46266 | J32: 4 | K32: 4 | L32: 232 | M32: Pipe Replacement scheduled or reactive task 031
A33: WO-2026-0032 | B33: Woodlands Hub | C33: Pipe Replacement | D33: Critical | E33: Closed | F33: Hari Kumar | G33: 46259 | H33: 46267 | I33: 46266 | J33: 5 | K33: 5 | L33: 267.5 | M33: Pipe Replacement scheduled or reactive task 032
A34: WO-2026-0033 | B34: Woodlands Hub | C34: Pump Service | D34: Low | E34: New | F34: Aisha Tan | G34: 46258 | H34: 46267 | J34: 6 | K34: 0 | L34: 303 | M34: Pump Service scheduled or reactive task 033
A35: WO-2026-0034 | B35: Jurong Depot | C35: Pump Service | D35: Medium | E35: Assigned | F35: Ben Lim | G35: 46257 | H35: 46267 | J35: 7 | K35: 0 | L35: 338.5 | M35: Pump Service scheduled or reactive task 034
A36: WO-2026-0035 | B36: Jurong Depot | C36: Pump Service | D36: High | E36: In Progress | F36: Chloe Goh | G36: 46256 | H36: 46267 | J36: 8 | K36: 0 | L36: 374 | M36: Pump Service scheduled or reactive task 035
A37: WO-2026-0036 | B37: Jurong Depot | C37: Pump Service | D37: Critical | E37: Closed | F37: Daniel Lee | G37: 46255 | H37: 46267 | I37: 46267 | J37: 2 | K37: 9 | L37: 409.5 | M37: Pump Service scheduled or reactive task 036
A38: WO-2026-0037 | B38: Tampines Centre | C38: Meter Service | D38: Low | E38: Closed | F38: Elena Ong | G38: 46254 | H38: 46267 | I38: 46267 | J38: 3 | K38: 1 | L38: 445 | M38: Meter Service scheduled or reactive task 037
A39: WO-2026-0038 | B39: Tampines Centre | C39: Meter Service | D39: Medium | E39: Assigned | F39: Farid Rahman | G39: 46253 | H39: 46267 | J39: 4 | K39: 0 | L39: 480.5 | M39: Meter Service scheduled or reactive task 038
A40: WO-2026-0039 | B40: Tampines Centre | C40: Meter Service | D40: High | E40: In Progress | F40: Grace Ng | G40: 46252 | H40: 46267 | J40: 5 | K40: 0 | L40: 516 | M40: Meter Service scheduled or reactive task 039
...

Sheet Technicians
A1: Technician | B1: Primary_Category | C1: Available_Hours_Week | D1: Home_Site
A2: Aisha Tan | B2: Leak Repair | C2: 35 | D2: Woodlands Hub
A3: Ben Lim | B3: Leak Repair | C3: 30 | D3: Jurong Depot
A4: Chloe Goh | B4: Leak Repair | C4: 35 | D4: Tampines Centre
A5: Daniel Lee | B5: Leak Repair | C5: 30 | D5: Paya Lebar Office
A6: Elena Ong | B6: Valve Repair | C6: 35 | D6: Changi Workshop
A7: Farid Rahman | B7: Valve Repair | C7: 30 | D7: Woodlands Hub
A8: Grace Ng | B8: Valve Repair | C8: 35 | D8: Jurong Depot
A9: Hari Kumar | B9: Valve Repair | C9: 30 | D9: Tampines Centre

Sheet Control
A1: Metric | B1: Expected / control
A2: Report_Date | B2: 46295
A3: total | B3: 120
A4: closed | B4: 48
A5: cancelled | B5: 12
A6: backlog | B6: 60
A7: overdue | B7: 50
A8: unassigned_backlog | B8: 6
A9: on_time_closed | B9: 30
A10: on_time_rate | B10: 0.625
A11: cost | B11: 35827.5
A12: Backlog definition | B12: Status is neither Closed nor Cancelled
A13: Overdue definition | B13: Backlog and Due_Date strictly earlier than Report_Date
A14: On-time definition | B14: Closed_Date <= Due_Date; denominator Closed only
A15: Unknown assignment | B15: Blank Assigned_To stays blank; propose separately

Sheet Prompt_Log
A1: Step | B1: App / mode | C1: Prompt | D1: What Copilot did | E1: How I verified | F1: Decision

Sheet Checks
A1: Check | B1: Formula / evidence | C1: Result
A2: Total clean rows | B2: =ROWS(tblWorkOrders[Work_Order_ID])

Sheet .Rules
A1: ## SOURCE AND SCOPE
A2: Preserve Work_Orders, tblWorkOrders, Technicians, current Assigned_To values and source IDs.
A3: Use the reporting date from Control!B2. State the selected Site, Job_Category, Status and Assigned_To scope beside every report.
A4: Backlog excludes Closed and Cancelled. Overdue backlog has Due_Date strictly before Control!B2.
A5: On-time closure rate uses Closed rows only, with Closed_Date <= Due_Date. Display N/A when no Closed rows remain.
A6: ## FORMATS AND VISUALS
A7: Display recorded Cost_SGD as S$ with two decimals; keep underlying values exact. Show dates as DD-MMM-YYYY.
A8: Use white backgrounds, navy titles, blue and teal accents, readable labels and named units; never use colour alone.
A9: ## DASHBOARD LAYOUT
A10: Dashboard sheet: title in A1; Site, Job_Category, Status and Assigned_To dropdowns in B2:B5 (All plus source values); the six measures in B7:B12; data-as-at date and selected scope in D2.
A11: Six KPI tiles in D4:I7, one column per tile: title in row 4, large value in row 5, short definition in row 6 and "Checks: PASS" in row 7.
A12: Charts in a grid below the tiles: work orders by status and by job category side by side, then a full-width stacked bar by site (overdue backlog, other backlog, Closed, Cancelled).
... A22: Ask before replacing named output sheets. Reconcile every count, rate and chart against source rows; do not duplicate outputs on rerun.
A23: ="Reporting date: "&TEXT(Control!B2,"yyyy-mm-dd")

Sheet Pareto_Job_Category
A1: Job_Category | B1: Count | C1: Cumulative_Count | D1: Share | E1: Cumulative_Percent
A2: Pump Service | B2: =COUNTIFS(tblWorkOrders[Job_Category],A2,tblWorkOrders[Status],"<>Closed",tblWorkOrders[Status],"<>Cancelled",tblWorkOrders[Due_Date],"<"&Control!$B$2) | C2: =SUM($B$2:B2) | D2: =IF(SUM($B$2:$B$6)=0,"N/A",B2/SUM($B$2:$B$6)) | E2: =IF(SUM($B$2:$B$6)=0,"N/A",C2/SUM($B$2:$B$6))
A3: Meter Service | B3: =COUNTIFS(tblWorkOrders[Job_Category],A3,tblWorkOrders[Status],"<>Closed",tblWorkOrders[Status],"<>Cancelled",tblWorkOrders[Due_Date],"<"&Control!$B$2) | C3: =SUM($B$2:B3) | D3: =IF(SUM($B$2:$B$6)=0,"N/A",B3/SUM($B$2:$B$6)) | E3: =IF(SUM($B$2:$B$6)=0,"N/A",C3/SUM($B$2:$B$6))
A4: Leak Repair | B4: =COUNTIFS(tblWorkOrders[Job_Category],A4,tblWorkOrders[Status],"<>Closed",tblWorkOrders[Status],"<>Cancelled",tblWorkOrders[Due_Date],"<"&Control!$B$2) | C4: =SUM($B$2:B4) | D4: =IF(SUM($B$2:$B$6)=0,"N/A",B4/SUM($B$2:$B$6)) | E4: =IF(SUM($B$2:$B$6)=0,"N/A",C4/SUM($B$2:$B$6))
A5: Valve Repair | B5: =COUNTIFS(tblWorkOrders[Job_Category],A5,tblWorkOrders[Status],"<>Closed",tblWorkOrders[Status],"<>Cancelled",tblWorkOrders[Due_Date],"<"&Control!$B$2) | C5: =SUM($B$2:B5) | D5: =IF(SUM($B$2:$B$6)=0,"N/A",B5/SUM($B$2:$B$6)) | E5: =IF(SUM($B$2:$B$6)=0,"N/A",C5/SUM($B$2:$B$6))
A6: Pipe Replacement | B6: =COUNTIFS(tblWorkOrders[Job_Category],A6,tblWorkOrders[Status],"<>Closed",tblWorkOrders[Status],"<>Cancelled",tblWorkOrders[Due_Date],"<"&Control!$B$2) | C6: =SUM($B$2:B6) | D6: =IF(SUM($B$2:$B$6)=0,"N/A",B6/SUM($B$2:$B$6)) | E6: =IF(SUM($B$2:$B$6)=0,"N/A",C6/SUM($B$2:$B$6))
A8: Reporting date | B8: =Control!B2
A9: Scope | B9: All; overdue backlog only
A10: Interpretation | B10: Four categories first reach80%; counts show contribution, not cause.
